Workbook

Sheet TIMESHEETS
G1: LAKNORD | BA1: 2014 | BB1: 1 | BC1: 41623 | BD1: 41636
BA2: 2014 | BB2: 2 | BC2: 41637 | BD2: 41650
W3: M | X3: = Maladie | BA3: 2014 | BB3: 3 | BC3: 41651 | BD3: 41664
G4: Time sheet | W4: F | X4: = Congé férié | BA4: 2014 | BB4: 4 | BC4: 41665 | BD4: 41678
W5: V | X5: = Vacances | BA5: 2014 | BB5: 5 | BC5: 41679 | BD5: 41692
W6: A | X6: = Absence sans paye | BA6: 2014 | BB6: 6 | BC6: 41693 | BD6: 41706
B7: Période de paye | G7: Période (jj/mm/aaaa) | K7: Période (jj/mm/aaaa) | W7: O | X7: = Autre (spécifier la raison dans les commentaires) | BA7: 2014 | BB7: 7 | BC7: 41707 | BD7: 41720
D8: Année | BA8: 2014 | BB8: 8 | BC8: 41721 | BD8: 41734
B9: 10 | D9: 2021 | E9: du | G9: 44311 | J9: au | K9: =IF(G9="","",G9+13) -> 44324 | P9: Heures rég./Bi-Hebdo. | U9: 80 | BA9: 2014 | BB9: 9 | BC9: 41735 | BD9: 41748
AM10: Total | AU10: Total | BA10: 2014 | BB10: 10 | BC10: 41749 | BD10: 41762
D11: No. d'employé | E11: Dept. | G11: =G9 -> 44311 | I11: =IF(G11="","",G11+1) -> 44312 | K11: =IF(I11="","",I11+1) -> 44313 | M11: =IF(K11="","",K11+1) -> 44314 | O11: =IF(M11="","",M11+1) -> 44315 | Q11: =IF(O11="","",O11+1) -> 44316 | S11: =IF(Q11="","",Q11+1) -> 44317 | W11: =IF(S11="","",S11+1) -> 44318 | Y11: =IF(W11="","",W11+1) -> 44319 | AA11: =IF(Y11="","",Y11+1) -> 44320 | AC11: =IF(AA11="","",AA11+1) -> 44321 | AE11: =IF(AC11="","",AC11+1) -> 44322 | AG11: =IF(AE11="","",AE11+1) -> 44323 | AI11: =IF(AG11="","",AG11+1) -> 44324 | AM11: Régulier | AN11: Overtime | AO11: Maladie | AP11: Congé férié | AQ11: Vacance | AR11: Autres | AS11: HEURES À PAYER | AU11: Absence | AW11: Reg. Hrs/sem | BA11: 2014 | BB11: 11 | BC11: 41763 | BD11: 41776
B12: Nom, Prénom | G12: Dim | I12: Lun | K12: Mar | M12: Mer | O12: Jeu | Q12: Ven | S12: Sam | U12: TOTAL | W12: Dim | Y12: Lun | AA12: Mar | AC12: Mer | AE12: Jeu | AG12: Ven | AI12: Sam | AK12: TOTAL | BA12: 2014 | BB12: 12 | BC12: 41777 | BD12: 41790
BA13: 2014 | BB13: 13 | BC13: 41791 | BD13: 41804
D14: 23919 | F14: =B9 -> 10 | J14: O | L14: O | N14: O | P14: O | R14: O | Z14: O | AB14: O | AD14: O | AF14: O | AH14: O | BA14: 2014 | BB14: 14 | BC14: 41805 | BD14: 41818
B15: Achour, Kheir Eddine | E15: 93545 | F15: =B9 -> 10 | J15: 0 | L15: 0 | N15: 0 | P15: 0 | R15: 0 | U15: =SUM(G15:T15) -> 0 | Z15: 0 | AB15: 0 | AD15: 0 | AF15: 0 | AH15: 0 | AK15: =SUM(W15:AJ15) -> 0 | AM15: =SUMIF($G14:$T14,"",$G15:$T15)+SUMIF($W14:$AJ14,"",$W15:$AJ15)-AN15 -> 0 | AN15: =IF(SUMIF($G14:$T14,"",$G15:$T15)+SUMIF($G14:$T14,"F",$G15:$T15)+SUMIF($G14:$T14,"V",$G15:$T15)-40<0,0,SUMIF($G14:$T14,"",$G15:$T15)+SUMIF($G14:$T14,"F",$G15:$T15)+SUMIF($G14:$T14,"V",$G15:$T15)-($U$9/2))+IF(SUMIF($W14:$AJ14,"",$W15:$AJ15)+SUMIF($W14:$AJ14,"F",$W15:$AJ15)+SUMIF($W14:$AJ14,"V",$W15:$AJ15)-40<0,0,SUMIF($W14:$AJ14,"",$W15:$AJ15)+SUMIF($W14:$AJ14,"F",$W15:$AJ15)+SUMIF($W14:$AJ14,"V",$W15:$AJ15)-($U$9/2)) -> 0 | AO15: =SUMIF($G14:$T14,"M",$G15:$T15)+SUMIF($W14:$AJ14,"M",$W15:$AJ15) -> 0 | AP15: =SUMIF($G14:$T14,"F",$G15:$T15)+SUMIF($W14:$AJ14,"F",$W15:$AJ15) -> 0 | AQ15: =SUMIF($G14:$T14,"V",$G15:$T15)+SUMIF($W14:$AJ14,"V",$W15:$AJ15) -> 0 | AR15: =SUMIF($G14:$T14,"O",$G15:$T15)+SUMIF($W14:$AJ14,"O",$W15:$AJ15) -> 0 | AS15: =SUM(AM15:AR15) -> 0 | AU15: 0 | AW15: 80 | BA15: 2014 | BB15: 15 | BC15: 41819 | BD15: 41832
D16: 24287 | F16: =B9 -> 10 | BA16: 2014 | BB16: 16 | BC16: 41833 | BD16: 41846
B17: Barrata, Dominic(Avance $500.00) | E17: 93595935 | F17: =B9 -> 10 | J17: COMM | L17: COMM | N17: COMM | P17: COMM | R17: COMM | U17: =SUM(G17:T17) -> 0 | Z17: COMM | AB17: COMM | AD17: COMM | AF17: COMM | AH17: COMM | AK17: =SUM(W17:AJ17) -> 0 | AM17: =SUMIF($G16:$T16,"",$G17:$T17)+SUMIF($W16:$AJ16,"",$W17:$AJ17)-AN17 -> 0 | AN17: =IF(SUMIF($G16:$T16,"",$G17:$T17)+SUMIF($G16:$T16,"F",$G17:$T17)+SUMIF($G16:$T16,"V",$G17:$T17)-40<0,0,SUMIF($G16:$T16,"",$G17:$T17)+SUMIF($G16:$T16,"F",$G17:$T17)+SUMIF($G16:$T16,"V",$G17:$T17)-($U$9/2))+IF(SUMIF($W16:$AJ16,"",$W17:$AJ17)+SUMIF($W16:$AJ16,"F",$W17:$AJ17)+SUMIF($W16:$AJ16,"V",$W17:$AJ17)-40<0,0,SUMIF($W16:$AJ16,"",$W17:$AJ17)+SUMIF($W16:$AJ16,"F",$W17:$AJ17)+SUMIF($W16:$AJ16,"V",$W17:$AJ17)-($U$9/2)) -> 0 | AO17: =SUMIF($G16:$T16,"M",$G17:$T17)+SUMIF($W16:$AJ16,"M",$W17:$AJ17) -> 0 | AP17: =SUMIF($G16:$T16,"F",$G17:$T17)+SUMIF($W16:$AJ16,"F",$W17:$AJ17) -> 0 | AQ17: =SUMIF($G16:$T16,"V",$G17:$T17)+SUMIF($W16:$AJ16,"V",$W17:$AJ17) -> 0 | AR17: =SUMIF($G16:$T16,"O",$G17:$T17)+SUMIF($W16:$AJ16,"O",$W17:$AJ17) -> 0 | AS17: =SUM(AM17:AR17) -> 0 | AU17: 0 | AW17: 80 | BA17: 2014 | BB17: 17 | BC17: 41847 | BD17: 41860
D18: 92032 | F18: =B9 -> 10 | BA18: 2014 | BB18: 18 | BC18: 41861 | BD18: 41874
B19: Benoit, Jean-Paul(Avance $1,600.00) | E19: 93595935 | F19: =B9 -> 10 | J19: COMM | L19: COMM | N19: COMM | P19: COMM | R19: COMM | U19: =SUM(G19:T19) -> 0 | Z19: COMM | AB19: COMM | AD19: COMM | AF19: COMM | AH19: COMM | AK19: =SUM(W19:AJ19) -> 0 | AM19: =SUMIF($G18:$T18,"",$G19:$T19)+SUMIF($W18:$AJ18,"",$W19:$AJ19)-AN19 -> 0 | AN19: =IF(SUMIF($G18:$T18,"",$G19:$T19)+SUMIF($G18:$T18,"F",$G19:$T19)+SUMIF($G18:$T18,"V",$G19:$T19)-40<0,0,SUMIF($G18:$T18,"",$G19:$T19)+SUMIF($G18:$T18,"F",$G19:$T19)+SUMIF($G18:$T18,"V",$G19:$T19)-($U$9/2))+IF(SUMIF($W18:$AJ18,"",$W19:$AJ19)+SUMIF($W18:$AJ18,"F",$W19:$AJ19)+SUMIF($W18:$AJ18,"V",$W19:$AJ19)-40<0,0,SUMIF($W18:$AJ18,"",$W19:$AJ19)+SUMIF($W18:$AJ18,"F",$W19:$AJ19)+SUMIF($W18:$AJ18,"V",$W19:$AJ19)-($U$9/2)) -> 0 | AO19: =SUMIF($G18:$T18,"M",$G19:$T19)+SUMIF($W18:$AJ18,"M",$W19:$AJ19) -> 0 | AP19: =SUMIF($G18:$T18,"F",$G19:$T19)+SUMIF($W18:$AJ18,"F",$W19:$AJ19) -> 0 | AQ19: =SUMIF($G18:$T18,"V",$G19:$T19)+SUMIF($W18:$AJ18,"V",$W19:$AJ19) -> 0 | AR19: =SUMIF($G18:$T18,"O",$G19:$T19)+SUMIF($W18:$AJ18,"O",$W19:$AJ19) -> 0 | AS19: =SUM(AM19:AR19) -> 0 | AU19: 0 | AW19: 80 | BA19: 2014 | BB19: 19 | BC19: 41875 | BD19: 41888
D20: 81077 | F20: =B9 -> 10 | BA20: 2014 | BB20: 20 | BC20: 41889 | BD20: 41902
B21: Bourassa, Julie | E21: 93540 | F21: =B9 -> 10 | J21: 8 | L21: 8 | N21: 9.25 | P21: 8 | R21: 8 | U21: =SUM(G21:T21) -> 41.25 | Z21: 8 | AB21: 8 | AD21: 8 | AF21: 9 | AH21: 9 | AK21: =SUM(W21:AJ21) -> 42 | AM21: =SUMIF($G20:$T20,"",$G21:$T21)+SUMIF($W20:$AJ20,"",$W21:$AJ21)-AN21 -> 80 | AN21: =IF(SUMIF($G20:$T20,"",$G21:$T21)+SUMIF($G20:$T20,"F",$G21:$T21)+SUMIF($G20:$T20,"V",$G21:$T21)-40<0,0,SUMIF($G20:$T20,"",$G21:$T21)+SUMIF($G20:$T20,"F",$G21:$T21)+SUMIF($G20:$T20,"V",$G21:$T21)-($U$9/2))+IF(SUMIF($W20:$AJ20,"",$W21:$AJ21)+SUMIF($W20:$AJ20,"F",$W21:$AJ21)+SUMIF($W20:$AJ20,"V",$W21:$AJ21)-40<0,0,SUMIF($W20:$AJ20,"",$W21:$AJ21)+SUMIF($W20:$AJ20,"F",$W21:$AJ21)+SUMIF($W20:$AJ20,"V",$W21:$AJ21)-($U$9/2)) -> 3.25 | AO21: =SUMIF($G20:$T20,"M",$G21:$T21)+SUMIF($W20:$AJ20,"M",$W21:$AJ21) -> 0 | AP21: =SUMIF($G20:$T20,"F",$G21:$T21)+SUMIF($W20:$AJ20,"F",$W21:$AJ21) -> 0 | AQ21: =SUMIF($G20:$T20,"V",$G21:$T21)+SUMIF($W20:$AJ20,"V",$W21:$AJ21) -> 0 | AR21: =SUMIF($G20:$T20,"O",$G21:$T21)+SUMIF($W20:$AJ20,"O",$W21:$AJ21) -> 0 | AS21: =SUM(AM21:AR21) -> 83.25 | AU21: 0 | AW21: 80 | BA21: 2014 | BB21: 21 | BC21: 41903 | BD21: 41916
D22: 78475 | F22: =B9 -> 10 | R22: V | BA22: 2014 | BB22: 22 | BC22: 41917 | BD22: 41930
B23: Charbonneau, Samuel | E23: 93540 | F23: =B9 -> 10 | J23: 8.5 | L23: 8.5 | N23: 8.5 | P23: 8.5 | R23: 8 | U23: =SUM(G23:T23) -> 42 | Z23: 8.5 | AB23: 8.5 | AD23: 8.5 | AF23: 8.5 | AH23: 8 | AK23: =SUM(W23:AJ23) -> 42 | AM23: =SUMIF($G22:$T22,"",$G23:$T23)+SUMIF($W22:$AJ22,"",$W23:$AJ23)-AN23 -> 72 | AN23: =IF(SUMIF($G22:$T22,"",$G23:$T23)+SUMIF($G22:$T22,"F",$G23:$T23)+SUMIF($G22:$T22,"V",$G23:$T23)-40<0,0,SUMIF($G22:$T22,"",$G23:$T23)+SUMIF($G22:$T22,"F",$G23:$T23)+SUMIF($G22:$T22,"V",$G23:$T23)-($U$9/2))+IF(SUMIF($W22:$AJ22,"",$W23:$AJ23)+SUMIF($W22:$AJ22,"F",$W23:$AJ23)+SUMIF($W22:$AJ22,"V",$W23:$AJ23)-40<0,0,SUMIF($W22:$AJ22,"",$W23:$AJ23)+SUMIF($W22:$AJ22,"F",$W23:$AJ23)+SUMIF($W22:$AJ22,"V",$W23:$AJ23)-($U$9/2)) -> 4 | AO23: =SUMIF($G22:$T22,"M",$G23:$T23)+SUMIF($W22:$AJ22,"M",$W23:$AJ23) -> 0 | AP23: =SUMIF($G22:$T22,"F",$G23:$T23)+SUMIF($W22:$AJ22,"F",$W23:$AJ23) -> 0 | AQ23: =SUMIF($G22:$T22,"V",$G23:$T23)+SUMIF($W22:$AJ22,"V",$W23:$AJ23) -> 8 | AR23: =SUMIF($G22:$T22,"O",$G23:$T23)+SUMIF($W22:$AJ22,"O",$W23:$AJ23) -> 0 | AS23: =SUM(AM23:AR23) -> 84 | AU23: 0 | AW23: 80 | BA23: 2014 | BB23: 23 | BC23: 41931 | BD23: 41944
D24: 24238 | F24: =B9 -> 10 | BA24: 2014 | BB24: 24 | BC24: 41945 | BD24: 41958
B25: Curtis, Jason | E25: 93595935 | F25: =B9 -> 10 | J25: 8 | L25: 8 | N25: 8 | P25: 8 | R25: 8 | U25: =SUM(G25:T25) -> 40 | Z25: 8 | AB25: 8 | AD25: 8 | AF25: 8 | AH25: 8 | AK25: =SUM(W25:AJ25) -> 40 | AM25: =SUMIF($G24:$T24,"",$G25:$T25)+SUMIF($W24:$AJ24,"",$W25:$AJ25)-AN25 -> 80 | AN25: =IF(SUMIF($G24:$T24,"",$G25:$T25)+SUMIF($G24:$T24,"F",$G25:$T25)+SUMIF($G24:$T24,"V",$G25:$T25)-40<0,0,SUMIF($G24:$T24,"",$G25:$T25)+SUMIF($G24:$T24,"F",$G25:$T25)+SUMIF($G24:$T24,"V",$G25:$T25)-($U$9/2))+IF(SUMIF($W24:$AJ24,"",$W25:$AJ25)+SUMIF($W24:$AJ24,"F",$W25:$AJ25)+SUMIF($W24:$AJ24,"V",$W25:$AJ25)-40<0,0,SUMIF($W24:$AJ24,"",$W25:$AJ25)+SUMIF($W24:$AJ24,"F",$W25:$AJ25)+SUMIF($W24:$AJ24,"V",$W25:$AJ25)-($U$9/2)) -> 0 | AO25: =SUMIF($G24:$T24,"M",$G25:$T25)+SUMIF($W24:$AJ24,"M",$W25:$AJ25) -> 0 | AP25: =SUMIF($G24:$T24,"F",$G25:$T25)+SUMIF($W24:$AJ24,"F",$W25:$AJ25) -> 0 | AQ25: =SUMIF($G24:$T24,"V",$G25:$T25)+SUMIF($W24:$AJ24,"V",$W25:$AJ25) -> 0 | AR25: =SUMIF($G24:$T24,"O",$G25:$T25)+SUMIF($W24:$AJ24,"O",$W25:$AJ25) -> 0 | AS25: =SUM(AM25:AR25) -> 80 | AU25: 0 | AW25: 80 | BA25: 2014 | BB25: 25 | BC25: 41959 | BD25: 41972
D26: 79709 | F26: =B9 -> 10 | BA26: 2014 | BB26: 26 | BC26: 41973 | BD26: 41986
B27: De Rose, Natale | E27: 93595935 | F27: =B9 -> 10 | J27: 8 | L27: 8 | N27: 8 | P27: 8 | R27: 8 | U27: =SUM(G27:T27) -> 40 | Z27: 8 | AB27: 8 | AD27: 8 | AF27: 8 | AH27: 8 | AK27: =SUM(W27:AJ27) -> 40 | AM27: =SUMIF($G26:$T26,"",$G27:$T27)+SUMIF($W26:$AJ26,"",$W27:$AJ27)-AN27 -> 80 | AN27: =IF(SUMIF($G26:$T26,"",$G27:$T27)+SUMIF($G26:$T26,"F",$G27:$T27)+SUMIF($G26:$T26,"V",$G27:$T27)-40<0,0,SUMIF($G26:$T26,"",$G27:$T27)+SUMIF($G26:$T26,"F",$G27:$T27)+SUMIF($G26:$T26,"V",$G27:$T27)-($U$9/2))+IF(SUMIF($W26:$AJ26,"",$W27:$AJ27)+SUMIF($W26:$AJ26,"F",$W27:$AJ27)+SUMIF($W26:$AJ26,"V",$W27:$AJ27)-40<0,0,SUMIF($W26:$AJ26,"",$W27:$AJ27)+SUMIF($W26:$AJ26,"F",$W27:$AJ27)+SUMIF($W26:$AJ26,"V",$W27:$AJ27)-($U$9/2)) -> 0 | AO27: =SUMIF($G26:$T26,"M",$G27:$T27)+SUMIF($W26:$AJ26,"M",$W27:$AJ27) -> 0 | AP27: =SUMIF($G26:$T26,"F",$G27:$T27)+SUMIF($W26:$AJ26,"F",$W27:$AJ27) -> 0 | AQ27: =SUMIF($G26:$T26,"V",$G27:$T27)+SUMIF($W26:$AJ26,"V",$W27:$AJ27) -> 0 | AR27: =SUMIF($G26:$T26,"O",$G27:$T27)+SUMIF($W26:$AJ26,"O",$W27:$AJ27) -> 0 | AS27: =SUM(AM27:AR27) -> 80 | AU27: 0 | AW27: 80 | BA27: 2014 | BB27: 27 | BC27: 41987 | BD27: 42000
D28: 92027 | F28: =B9 -> 10 | BA28: 2015 | BB28: 1 | BC28: 42001 | BD28: 42014
B29: Descoteaux, Gerald | E29: 93595935 | F29: =B9 -> 10 | J29: 8 | L29: 8 | N29: 8 | P29: 8 | R29: 8 | U29: =SUM(G29:T29) -> 40 | Z29: 8 | AB29: 8 | AD29: 8 | AF29: 8 | AH29: 8 | AK29: =SUM(W29:AJ29) -> 40 | AM29: =SUMIF($G28:$T28,"",$G29:$T29)+SUMIF($W28:$AJ28,"",$W29:$AJ29)-AN29 -> 80 | AN29: =IF(SUMIF($G28:$T28,"",$G29:$T29)+SUMIF($G28:$T28,"F",$G29:$T29)+SUMIF($G28:$T28,"V",$G29:$T29)-40<0,0,SUMIF($G28:$T28,"",$G29:$T29)+SUMIF($G28:$T28,"F",$G29:$T29)+SUMIF($G28:$T28,"V",$G29:$T29)-($U$9/2))+IF(SUMIF($W28:$AJ28,"",$W29:$AJ29)+SUMIF($W28:$AJ28,"F",$W29:$AJ29)+SUMIF($W28:$AJ28,"V",$W29:$AJ29)-40<0,0,SUMIF($W28:$AJ28,"",$W29:$AJ29)+SUMIF($W28:$AJ28,"F",$W29:$AJ29)+SUMIF($W28:$AJ28,"V",$W29:$AJ29)-($U$9/2)) -> 0 | AO29: =SUMIF($G28:$T28,"M",$G29:$T29)+SUMIF($W28:$AJ28,"M",$W29:$AJ29) -> 0 | AP29: =SUMIF($G28:$T28,"F",$G29:$T29)+SUMIF($W28:$AJ28,"F",$W29:$AJ29) -> 0 | AQ29: =SUMIF($G28:$T28,"V",$G29:$T29)+SUMIF($W28:$AJ28,"V",$W29:$AJ29) -> 0 | AR29: =SUMIF($G28:$T28,"O",$G29:$T29)+SUMIF($W28:$AJ28,"O",$W29:$AJ29) -> 0 | AS29: =SUM(AM29:AR29) -> 80 | AU29: 0 | AW29: 80 | BA29: 2015 | BB29: 2 | BC29: 42015 | BD29: 42028
D30: 73795 | F30: =B9 -> 10 | BA30: 2015 | BB30: 3 | BC30: 42029 | BD30: 42042
B31: Fortin, Veronique | E31: 93540 | F31: =B9 -> 10 | J31: 8 | L31: 8 | N31: 8 | P31: 8 | R31: 7.5 | U31: =SUM(G31:T31) -> 39.5 | Z31: 8 | AB31: 8 | AD31: 8 | AF31: 8 | AH31: 7.5 | AK31: =SUM(W31:AJ31) -> 39.5 | AM31: =SUMIF($G30:$T30,"",$G31:$T31)+SUMIF($W30:$AJ30,"",$W31:$AJ31)-AN31 -> 79 | AN31: =IF(SUMIF($G30:$T30,"",$G31:$T31)+SUMIF($G30:$T30,"F",$G31:$T31)+SUMIF($G30:$T30,"V",$G31:$T31)-40<0,0,SUMIF($G30:$T30,"",$G31:$T31)+SUMIF($G30:$T30,"F",$G31:$T31)+SUMIF($G30:$T30,"V",$G31:$T31)-($U$9/2))+IF(SUMIF($W30:$AJ30,"",$W31:$AJ31)+SUMIF($W30:$AJ30,"F",$W31:$AJ31)+SUMIF($W30:$AJ30,"V",$W31:$AJ31)-40<0,0,SUMIF($W30:$AJ30,"",$W31:$AJ31)+SUMIF($W30:$AJ30,"F",$W31:$AJ31)+SUMIF($W30:$AJ30,"V",$W31:$AJ31)-($U$9/2)) -> 0 | AO31: =SUMIF($G30:$T30,"M",$G31:$T31)+SUMIF($W30:$AJ30,"M",$W31:$AJ31) -> 0 | AP31: =SUMIF($G30:$T30,"F",$G31:$T31)+SUMIF($W30:$AJ30,"F",$W31:$AJ31) -> 0 | AQ31: =SUMIF($G30:$T30,"V",$G31:$T31)+SUMIF($W30:$AJ30,"V",$W31:$AJ31) -> 0 | AR31: =SUMIF($G30:$T30,"O",$G31:$T31)+SUMIF($W30:$AJ30,"O",$W31:$AJ31) -> 0 | AS31: =SUM(AM31:AR31) -> 79 | AU31: 0 | AW31: 80 | BA31: 2015 | BB31: 4 | BC31: 42043 | BD31: 42056
D32: 23206 | F32: =B9 -> 10 | AH32: A | BA32: 2015 | BB32: 5 | BC32: 42057 | BD32: 42070
B33: Gadbois, Dominic | E33: 93545 | F33: =B9 -> 10 | J33: 8 | L33: 8 | N33: 8 | P33: 8 | R33: 6.25 | U33: =SUM(G33:T33) -> 38.25 | Z33: 8 | AB33: 8 | AD33: 8 | AF33: 8 | AH33: 0 | AK33: =SUM(W33:AJ33) -> 32 | AM33: =SUMIF($G32:$T32,"",$G33:$T33)+SUMIF($W32:$AJ32,"",$W33:$AJ33)-AN33 -> 70.25 | AN33: =IF(SUMIF($G32:$T32,"",$G33:$T33)+SUMIF($G32:$T32,"F",$G33:$T33)+SUMIF($G32:$T32,"V",$G33:$T33)-40<0,0,SUMIF($G32:$T32,"",$G33:$T33)+SUMIF($G32:$T32,"F",$G33:$T33)+SUMIF($G32:$T32,"V",$G33:$T33)-($U$9/2))+IF(SUMIF($W32:$AJ32,"",$W33:$AJ33)+SUMIF($W32:$AJ32,"F",$W33:$AJ33)+SUMIF($W32:$AJ32,"V",$W33:$AJ33)-40<0,0,SUMIF($W32:$AJ32,"",$W33:$AJ33)+SUMIF($W32:$AJ32,"F",$W33:$AJ33)+SUMIF($W32:$AJ32,"V",$W33:$AJ33)-($U$9/2)) -> 0 | AO33: =SUMIF($G32:$T32,"M",$G33:$T33)+SUMIF($W32:$AJ32,"M",$W33:$AJ33) -> 0 | AP33: =SUMIF($G32:$T32,"F",$G33:$T33)+SUMIF($W32:$AJ32,"F",$W33:$AJ33) -> 0 | AQ33: =SUMIF($G32:$T32,"V",$G33:$T33)+SUMIF($W32:$AJ32,"V",$W33:$AJ33) -> 0 | AR33: =SUMIF($G32:$T32,"O",$G33:$T33)+SUMIF($W32:$AJ32,"O",$W33:$AJ33) -> 0 | AS33: =SUM(AM33:AR33) -> 70.25 | AU33: 0 | AW33: 80 | BA33: 2015 | BB33: 6 | BC33: 42071 | BD33: 42084
D34: 33664 | F34: =B9 -> 10 | BA34: 2015 | BB34: 7 | BC34: 42085 | BD34: 42098
B35: Knox Michaud, Jessy | E35: 93542 | F35: =B9 -> 10 | J35: 8.5 | L35: 8.25 | N35: 8 | P35: 8 | R35: 8 | U35: =SUM(G35:T35) -> 40.75 | Z35: 8 | AB35: 8.5 | AD35: 8 | AF35: 8 | AH35: 8 | AK35: =SUM(W35:AJ35) -> 40.5 | AM35: =SUMIF($G34:$T34,"",$G35:$T35)+SUMIF($W34:$AJ34,"",$W35:$AJ35)-AN35 -> 80 | AN35: =IF(SUMIF($G34:$T34,"",$G35:$T35)+SUMIF($G34:$T34,"F",$G35:$T35)+SUMIF($G34:$T34,"V",$G35:$T35)-40<0,0,SUMIF($G34:$T34,"",$G35:$T35)+SUMIF($G34:$T34,"F",$G35:$T35)+SUMIF($G34:$T34,"V",$G35:$T35)-($U$9/2))+IF(SUMIF($W34:$AJ34,"",$W35:$AJ35)+SUMIF($W34:$AJ34,"F",$W35:$AJ35)+SUMIF($W34:$AJ34,"V",$W35:$AJ35)-40<0,0,SUMIF($W34:$AJ34,"",$W35:$AJ35)+SUMIF($W34:$AJ34,"F",$W35:$AJ35)+SUMIF($W34:$AJ34,"V",$W35:$AJ35)-($U$9/2)) -> 1.25 | AO35: =SUMIF($G34:$T34,"M",$G35:$T35)+SUMIF($W34:$AJ34,"M",$W35:$AJ35) -> 0 | AP35: =SUMIF($G34:$T34,"F",$G35:$T35)+SUMIF($W34:$AJ34,"F",$W35:$AJ35) -> 0 | AQ35: =SUMIF($G34:$T34,"V",$G35:$T35)+SUMIF($W34:$AJ34,"V",$W35:$AJ35) -> 0 | AR35: =SUMIF($G34:$T34,"O",$G35:$T35)+SUMIF($W34:$AJ34,"O",$W35:$AJ35) -> 0 | AS35: =SUM(AM35:AR35) -> 81.25 | AU35: 0 | AW35: 80 | BA35: 2015 | BB35: 8 | BC35: 42099 | BD35: 42112
D36: 14206 | F36: =B9 -> 10 | R36: V | BA36: 2015 | BB36: 9 | BC36: 42113 | BD36: 42126
B37: Landry, Bernard | E37: 93545 | F37: =B9 -> 10 | J37: 8 | L37: 8 | N37: 8 | P37: 8 | R37: 8 | U37: =SUM(G37:T37) -> 40 | Z37: 8 | AB37: 8 | AD37: 8 | AF37: 8 | AH37: 8 | AK37: =SUM(W37:AJ37) -> 40 | AM37: =SUMIF($G36:$T36,"",$G37:$T37)+SUMIF($W36:$AJ36,"",$W37:$AJ37)-AN37 -> 72 | AN37: =IF(SUMIF($G36:$T36,"",$G37:$T37)+SUMIF($G36:$T36,"F",$G37:$T37)+SUMIF($G36:$T36,"V",$G37:$T37)-40<0,0,SUMIF($G36:$T36,"",$G37:$T37)+SUMIF($G36:$T36,"F",$G37:$T37)+SUMIF($G36:$T36,"V",$G37:$T37)-($U$9/2))+IF(SUMIF($W36:$AJ36,"",$W37:$AJ37)+SUMIF($W36:$AJ36,"F",$W37:$AJ37)+SUMIF($W36:$AJ36,"V",$W37:$AJ37)-40<0,0,SUMIF($W36:$AJ36,"",$W37:$AJ37)+SUMIF($W36:$AJ36,"F",$W37:$AJ37)+SUMIF($W36:$AJ36,"V",$W37:$AJ37)-($U$9/2)) -> 0 | AO37: =SUMIF($G36:$T36,"M",$G37:$T37)+SUMIF($W36:$AJ36,"M",$W37:$AJ37) -> 0 | AP37: =SUMIF($G36:$T36,"F",$G37:$T37)+SUMIF($W36:$AJ36,"F",$W37:$AJ37) -> 0 | AQ37: =SUMIF($G36:$T36,"V",$G37:$T37)+SUMIF($W36:$AJ36,"V",$W37:$AJ37) -> 8 | AR37: =SUMIF($G36:$T36,"O",$G37:$T37)+SUMIF($W36:$AJ36,"O",$W37:$AJ37) -> 0 | AS37: =SUM(AM37:AR37) -> 80 | AU37: 0 | AW37: 80 | BA37: 2015 | BB37: 10 | BC37: 42127 | BD37: 42140
D38: 92257 | F38: =B9 -> 10 | J38: V | L38: V | N38: V | P38: V | R38: V | BA38: 2015 | BB38: 11 | BC38: 42141 | BD38: 42154
B39: Lelievre, Anik | E39: 93513 | F39: =B9 -> 10 | J39: 8 | L39: 8 | N39: 8 | P39: 8 | R39: 8 | U39: =SUM(G39:T39) -> 40 | Z39: 8 | AB39: 8 | AD39: 8 | AF39: 8 | AH39: 8 | AK39: =SUM(W39:AJ39) -> 40 | AM39: =SUMIF($G38:$T38,"",$G39:$T39)+SUMIF($W38:$AJ38,"",$W39:$AJ39)-AN39 -> 40 | AN39: =IF(SUMIF($G38:$T38,"",$G39:$T39)+SUMIF($G38:$T38,"F",$G39:$T39)+SUMIF($G38:$T38,"V",$G39:$T39)-40<0,0,SUMIF($G38:$T38,"",$G39:$T39)+SUMIF($G38:$T38,"F",$G39:$T39)+SUMIF($G38:$T38,"V",$G39:$T39)-($U$9/2))+IF(SUMIF($W38:$AJ38,"",$W39:$AJ39)+SUMIF($W38:$AJ38,"F",$W39:$AJ39)+SUMIF($W38:$AJ38,"V",$W39:$AJ39)-40<0,0,SUMIF($W38:$AJ38,"",$W39:$AJ39)+SUMIF($W38:$AJ38,"F",$W39:$AJ39)+SUMIF($W38:$AJ38,"V",$W39:$AJ39)-($U$9/2)) -> 0 | AO39: =SUMIF($G38:$T38,"M",$G39:$T39)+SUMIF($W38:$AJ38,"M",$W39:$AJ39) -> 0 | AP39: =SUMIF($G38:$T38,"F",$G39:$T39)+SUMIF($W38:$AJ38,"F",$W39:$AJ39) -> 0 | AQ39: =SUMIF($G38:$T38,"V",$G39:$T39)+SUMIF($W38:$AJ38,"V",$W39:$AJ39) -> 40 | AR39: =SUMIF($G38:$T38,"O",$G39:$T39)+SUMIF($W38:$AJ38,"O",$W39:$AJ39) -> 0 | AS39: =SUM(AM39:AR39) -> 80 | AU39: 0 | AW39: 80 | BA39: 2015 | BB39: 12 | BC39: 42155 | BD39: 42168
D40: 81042 | F40: =B9 -> 10 | N40: V | P40: V | R40: V | BA40: 2015 | BB40: 13 | BC40: 42169 | BD40: 42182
...

Sheet VACATION
G1: LAKNORD
G4: Vacances et | I4: maladie
J7: 10 | K7: =J7+1 -> 11 | L7: =K7+1 -> 12 | M7: =L7+1 -> 13 | N7: =M7+1 -> 14 | O7: =N7+1 -> 15 | P7: =O7+1 -> 16 | Q7: =P7+1 -> 17 | R7: =Q7+1 -> 18 | ... AA7: =Z7+1 -> 27 | AB7: 1 | AC7: =AB7+1 -> 2 | AD7: =AC7+1 -> 3 | AE7: =AD7+1 -> 4 | AF7: =AE7+1 -> 5 | AG7: =AF7+1 -> 6 | AH7: =AG7+1 -> 7 | AI7: =AH7+1 -> 8 | AJ7: =AI7+1 -> 9
B8: EMPLOYÉS | H8: HEURES VAC. | J8: ="PP"&TEXT(J7,"00")&" "&TEXT(SUMIFS(TIMESHEETS!$BD:$BD,TIMESHEETS!$BA:$BA,TIMESHEETS!$D$9,TIMESHEETS!$BB:$BB,J7),"MMM") -> PP10 mai | K8: ="PP"&TEXT(K7,"00")&" "&TEXT(SUMIFS(TIMESHEETS!$BD:$BD,TIMESHEETS!$BA:$BA,TIMESHEETS!$D$9,TIMESHEETS!$BB:$BB,K7),"MMM") -> PP11 mai | L8: ="PP"&TEXT(L7,"00")&" "&TEXT(SUMIFS(TIMESHEETS!$BD:$BD,TIMESHEETS!$BA:$BA,TIMESHEETS!$D$9,TIMESHEETS!$BB:$BB,L7),"MMM") -> PP12 juin | M8: ="PP"&TEXT(M7,"00")&" "&TEXT(SUMIFS(TIMESHEETS!$BD:$BD,TIMESHEETS!$BA:$BA,TIMESHEETS!$D$9,TIMESHEETS!$BB:$BB,M7),"MMM") -> PP13 juin | N8: ="PP"&TEXT(N7,"00")&" "&TEXT(SUMIFS(TIMESHEETS!$BD:$BD,TIMESHEETS!$BA:$BA,TIMESHEETS!$D$9,TIMESHEETS!$BB:$BB,N7),"MMM") -> PP14 juil | O8: ="PP"&TEXT(O7,"00")&" "&TEXT(SUMIFS(TIMESHEETS!$BD:$BD,TIMESHEETS!$BA:$BA,TIMESHEETS!$D$9,TIMESHEETS!$BB:$BB,O7),"MMM") -> PP15 juil | P8: ="PP"&TEXT(P7,"00")&" "&TEXT(SUMIFS(TIMESHEETS!$BD:$BD,TIMESHEETS!$BA:$BA,TIMESHEETS!$D$9,TIMESHEETS!$BB:$BB,P7),"MMM") -> PP16 juil | Q8: ="PP"&TEXT(Q7,"00")&" "&TEXT(SUMIFS(TIMESHEETS!$BD:$BD,TIMESHEETS!$BA:$BA,TIMESHEETS!$D$9,TIMESHEETS!$BB:$BB,Q7),"MMM") -> PP17 août | ... AI8: ="PP"&TEXT(AI7,"00")&" "&TEXT(SUMIFS(TIMESHEETS!$BD:$BD,TIMESHEETS!$BA:$BA,TIMESHEETS!$D$9,TIMESHEETS!$BB:$BB,AI7),"MMM") -> PP08 avr | AJ8: ="PP"&TEXT(AJ7,"00")&IF(SUMIFS(TIMESHEETS!$BD:$BD,TIMESHEETS!$BA:$BA,TIMESHEETS!$D$9,TIMESHEETS!$BB:$BB,AJ7)=0,""," "&TEXT(SUMIFS(TIMESHEETS!$BD:$BD,TIMESHEETS!$BA:$BA,TIMESHEETS!$D$9,TIMESHEETS!$BB:$BB,AJ7),"MMM")) -> PP09 avr | AL8: TOTAL | AM8: NBR Jour
B9: Nom, Prénom | E9: No. Employé | H9: MALADIE
B11: 44333 | H11: 16 | J11: =SUMIFS(TIMESHEETS!$AQ:$AQ,TIMESHEETS!$F:$F,J$7,TIMESHEETS!$B:$B,$B12) -> 0 | K11: =SUMIFS(TIMESHEETS!$AQ:$AQ,TIMESHEETS!$F:$F,K$7,TIMESHEETS!$B:$B,$B12) -> 0 | L11: =SUMIFS(TIMESHEETS!$AQ:$AQ,TIMESHEETS!$F:$F,L$7,TIMESHEETS!$B:$B,$B12) -> 0 | M11: =SUMIFS(TIMESHEETS!$AQ:$AQ,TIMESHEETS!$F:$F,M$7,TIMESHEETS!$B:$B,$B12) -> 0 | N11: =SUMIFS(TIMESHEETS!$AQ:$AQ,TIMESHEETS!$F:$F,N$7,TIMESHEETS!$B:$B,$B12) -> 0 | O11: =SUMIFS(TIMESHEETS!$AQ:$AQ,TIMESHEETS!$F:$F,O$7,TIMESHEETS!$B:$B,$B12) -> 0 | P11: =SUMIFS(TIMESHEETS!$AQ:$AQ,TIMESHEETS!$F:$F,P$7,TIMESHEETS!$B:$B,$B12) -> 0 | Q11: =SUMIFS(TIMESHEETS!$AQ:$AQ,TIMESHEETS!$F:$F,Q$7,TIMESHEETS!$B:$B,$B12) -> 0 | ... AE11: =SUMIFS(TIMESHEETS!$AQ:$AQ,TIMESHEETS!$F:$F,AE$7,TIMESHEETS!$B:$B,$B12) -> 0 | AF11: 0 | AG11: =SUMIFS(TIMESHEETS!$AQ:$AQ,TIMESHEETS!$F:$F,AG$7,TIMESHEETS!$B:$B,$B12) -> 0 | AH11: =SUMIFS(TIMESHEETS!$AQ:$AQ,TIMESHEETS!$F:$F,AH$7,TIMESHEETS!$B:$B,$B12) -> 0 | AI11: =SUMIFS(TIMESHEETS!$AQ:$AQ,TIMESHEETS!$F:$F,AI$7,TIMESHEETS!$B:$B,$B12) -> 0 | AJ11: =SUMIFS(TIMESHEETS!$AQ:$AQ,TIMESHEETS!$F:$F,AJ$7,TIMESHEETS!$B:$B,$B12) -> 0 | AL11: =H11-SUM(J11:AJ11) -> 0 | AM11: =AL11/8 -> 0
B12: Gaulin, Francis | H12: 16 | J12: =SUMIFS(TIMESHEETS!$AO:$AO,TIMESHEETS!$F:$F,J$7,TIMESHEETS!$B:$B,$B12) -> 0 | K12: =SUMIFS(TIMESHEETS!$AO:$AO,TIMESHEETS!$F:$F,K$7,TIMESHEETS!$B:$B,$B12) -> 0 | L12: =SUMIFS(TIMESHEETS!$AO:$AO,TIMESHEETS!$F:$F,L$7,TIMESHEETS!$B:$B,$B12) -> 0 | M12: =SUMIFS(TIMESHEETS!$AO:$AO,TIMESHEETS!$F:$F,M$7,TIMESHEETS!$B:$B,$B12) -> 0 | N12: =SUMIFS(TIMESHEETS!$AO:$AO,TIMESHEETS!$F:$F,N$7,TIMESHEETS!$B:$B,$B12) -> 0 | O12: =SUMIFS(TIMESHEETS!$AO:$AO,TIMESHEETS!$F:$F,O$7,TIMESHEETS!$B:$B,$B12) -> 0 | P12: =SUMIFS(TIMESHEETS!$AO:$AO,TIMESHEETS!$F:$F,P$7,TIMESHEETS!$B:$B,$B12) -> 0 | Q12: =SUMIFS(TIMESHEETS!$AO:$AO,TIMESHEETS!$F:$F,Q$7,TIMESHEETS!$B:$B,$B12) -> 0 | ... AJ12: =SUMIFS(TIMESHEETS!$AO:$AO,TIMESHEETS!$F:$F,AJ$7,TIMESHEETS!$B:$B,$B12) -> 8 | AL12: =H12-SUM(J12:AJ12) -> -8
B14: 38159 | H14: 160 | J14: =SUMIFS(TIMESHEETS!$AQ:$AQ,TIMESHEETS!$F:$F,J$7,TIMESHEETS!$B:$B,$B15) -> 0 | K14: =SUMIFS(TIMESHEETS!$AQ:$AQ,TIMESHEETS!$F:$F,K$7,TIMESHEETS!$B:$B,$B15) -> 0 | L14: =SUMIFS(TIMESHEETS!$AQ:$AQ,TIMESHEETS!$F:$F,L$7,TIMESHEETS!$B:$B,$B15) -> 0 | M14: =SUMIFS(TIMESHEETS!$AQ:$AQ,TIMESHEETS!$F:$F,M$7,TIMESHEETS!$B:$B,$B15) -> 0 | N14: =SUMIFS(TIMESHEETS!$AQ:$AQ,TIMESHEETS!$F:$F,N$7,TIMESHEETS!$B:$B,$B15) -> 0 | O14: =SUMIFS(TIMESHEETS!$AQ:$AQ,TIMESHEETS!$F:$F,O$7,TIMESHEETS!$B:$B,$B15) -> 0 | P14: =SUMIFS(TIMESHEETS!$AQ:$AQ,TIMESHEETS!$F:$F,P$7,TIMESHEETS!$B:$B,$B15) -> 0 | Q14: =SUMIFS(TIMESHEETS!$AQ:$AQ,TIMESHEETS!$F:$F,Q$7,TIMESHEETS!$B:$B,$B15) -> 0 | ... AJ14: =SUMIFS(TIMESHEETS!$AQ:$AQ,TIMESHEETS!$F:$F,AJ$7,TIMESHEETS!$B:$B,$B15) -> 0 | AL14: =H14-SUM(J14:AJ14) -> 8 | AM14: =AL14/8 -> 1
B15: Bourassa, Julie | H15: 16 | J15: =SUMIFS(TIMESHEETS!$AO:$AO,TIMESHEETS!$F:$F,J$7,TIMESHEETS!$B:$B,$B15) -> 0 | K15: =SUMIFS(TIMESHEETS!$AO:$AO,TIMESHEETS!$F:$F,K$7,TIMESHEETS!$B:$B,$B15) -> 0 | L15: =SUMIFS(TIMESHEETS!$AO:$AO,TIMESHEETS!$F:$F,L$7,TIMESHEETS!$B:$B,$B15) -> 0 | M15: =SUMIFS(TIMESHEETS!$AO:$AO,TIMESHEETS!$F:$F,M$7,TIMESHEETS!$B:$B,$B15) -> 0 | N15: =SUMIFS(TIMESHEETS!$AO:$AO,TIMESHEETS!$F:$F,N$7,TIMESHEETS!$B:$B,$B15) -> 0 | O15: =SUMIFS(TIMESHEETS!$AO:$AO,TIMESHEETS!$F:$F,O$7,TIMESHEETS!$B:$B,$B15) -> 0 | P15: =SUMIFS(TIMESHEETS!$AO:$AO,TIMESHEETS!$F:$F,P$7,TIMESHEETS!$B:$B,$B15) -> 0 | Q15: =SUMIFS(TIMESHEETS!$AO:$AO,TIMESHEETS!$F:$F,Q$7,TIMESHEETS!$B:$B,$B15) -> 0 | ... AJ15: =SUMIFS(TIMESHEETS!$AO:$AO,TIMESHEETS!$F:$F,AJ$7,TIMESHEETS!$B:$B,$B15) -> 0 | AL15: =H15-SUM(J15:AJ15) -> 0
B17: 42408 | H17: 128 | J17: =SUMIFS(TIMESHEETS!$AQ:$AQ,TIMESHEETS!$F:$F,J$7,TIMESHEETS!$B:$B,$B18) -> 8 | K17: =SUMIFS(TIMESHEETS!$AQ:$AQ,TIMESHEETS!$F:$F,K$7,TIMESHEETS!$B:$B,$B18) -> 0 | L17: =SUMIFS(TIMESHEETS!$AQ:$AQ,TIMESHEETS!$F:$F,L$7,TIMESHEETS!$B:$B,$B18) -> 8 | M17: =SUMIFS(TIMESHEETS!$AQ:$AQ,TIMESHEETS!$F:$F,M$7,TIMESHEETS!$B:$B,$B18) -> 0 | N17: =SUMIFS(TIMESHEETS!$AQ:$AQ,TIMESHEETS!$F:$F,N$7,TIMESHEETS!$B:$B,$B18) -> 0 | O17: =SUMIFS(TIMESHEETS!$AQ:$AQ,TIMESHEETS!$F:$F,O$7,TIMESHEETS!$B:$B,$B18) -> 0 | P17: =SUMIFS(TIMESHEETS!$AQ:$AQ,TIMESHEETS!$F:$F,P$7,TIMESHEETS!$B:$B,$B18) -> 80 | Q17: =SUMIFS(TIMESHEETS!$AQ:$AQ,TIMESHEETS!$F:$F,Q$7,TIMESHEETS!$B:$B,$B18) -> 0 | ... AJ17: =SUMIFS(TIMESHEETS!$AQ:$AQ,TIMESHEETS!$F:$F,AJ$7,TIMESHEETS!$B:$B,$B18) -> 0 | AL17: =H17-SUM(J17:AJ17) -> 0 | AM17: =AL17/8 -> 0
B18: Charbonneau, Samuel | H18: 16 | J18: =SUMIFS(TIMESHEETS!$AO:$AO,TIMESHEETS!$F:$F,J$7,TIMESHEETS!$B:$B,$B18) -> 0 | K18: =SUMIFS(TIMESHEETS!$AO:$AO,TIMESHEETS!$F:$F,K$7,TIMESHEETS!$B:$B,$B18) -> 0 | L18: =SUMIFS(TIMESHEETS!$AO:$AO,TIMESHEETS!$F:$F,L$7,TIMESHEETS!$B:$B,$B18) -> 0 | M18: =SUMIFS(TIMESHEETS!$AO:$AO,TIMESHEETS!$F:$F,M$7,TIMESHEETS!$B:$B,$B18) -> 0 | N18: =SUMIFS(TIMESHEETS!$AO:$AO,TIMESHEETS!$F:$F,N$7,TIMESHEETS!$B:$B,$B18) -> 0 | O18: =SUMIFS(TIMESHEETS!$AO:$AO,TIMESHEETS!$F:$F,O$7,TIMESHEETS!$B:$B,$B18) -> 0 | P18: =SUMIFS(TIMESHEETS!$AO:$AO,TIMESHEETS!$F:$F,P$7,TIMESHEETS!$B:$B,$B18) -> 0 | Q18: =SUMIFS(TIMESHEETS!$AO:$AO,TIMESHEETS!$F:$F,Q$7,TIMESHEETS!$B:$B,$B18) -> 8 | ... AJ18: =SUMIFS(TIMESHEETS!$AO:$AO,TIMESHEETS!$F:$F,AJ$7,TIMESHEETS!$B:$B,$B18) -> 0 | AL18: =H18-SUM(J18:AJ18) -> 0
H20: 0 | J20: =SUMIFS(TIMESHEETS!$AQ:$AQ,TIMESHEETS!$F:$F,J$7,TIMESHEETS!$B:$B,$B21) -> 0 | K20: =SUMIFS(TIMESHEETS!$AQ:$AQ,TIMESHEETS!$F:$F,K$7,TIMESHEETS!$B:$B,$B21) -> 0 | L20: =SUMIFS(TIMESHEETS!$AQ:$AQ,TIMESHEETS!$F:$F,L$7,TIMESHEETS!$B:$B,$B21) -> 0 | M20: =SUMIFS(TIMESHEETS!$AQ:$AQ,TIMESHEETS!$F:$F,M$7,TIMESHEETS!$B:$B,$B21) -> 0 | N20: =SUMIFS(TIMESHEETS!$AQ:$AQ,TIMESHEETS!$F:$F,N$7,TIMESHEETS!$B:$B,$B21) -> 0 | O20: =SUMIFS(TIMESHEETS!$AQ:$AQ,TIMESHEETS!$F:$F,O$7,TIMESHEETS!$B:$B,$B21) -> 0 | P20: =SUMIFS(TIMESHEETS!$AQ:$AQ,TIMESHEETS!$F:$F,P$7,TIMESHEETS!$B:$B,$B21) -> 0 | Q20: =SUMIFS(TIMESHEETS!$AQ:$AQ,TIMESHEETS!$F:$F,Q$7,TIMESHEETS!$B:$B,$B21) -> 0 | ... AJ20: =SUMIFS(TIMESHEETS!$AQ:$AQ,TIMESHEETS!$F:$F,AJ$7,TIMESHEETS!$B:$B,$B21) -> 0 | AL20: =H20-SUM(J20:AJ20) -> 0 | AM20: =AL20/8 -> 0
H21: 0 | J21: =SUMIFS(TIMESHEETS!$AO:$AO,TIMESHEETS!$F:$F,J$7,TIMESHEETS!$B:$B,$B21) -> 0 | K21: =SUMIFS(TIMESHEETS!$AO:$AO,TIMESHEETS!$F:$F,K$7,TIMESHEETS!$B:$B,$B21) -> 0 | L21: =SUMIFS(TIMESHEETS!$AO:$AO,TIMESHEETS!$F:$F,L$7,TIMESHEETS!$B:$B,$B21) -> 0 | M21: =SUMIFS(TIMESHEETS!$AO:$AO,TIMESHEETS!$F:$F,M$7,TIMESHEETS!$B:$B,$B21) -> 0 | N21: =SUMIFS(TIMESHEETS!$AO:$AO,TIMESHEETS!$F:$F,N$7,TIMESHEETS!$B:$B,$B21) -> 0 | O21: =SUMIFS(TIMESHEETS!$AO:$AO,TIMESHEETS!$F:$F,O$7,TIMESHEETS!$B:$B,$B21) -> 0 | P21: =SUMIFS(TIMESHEETS!$AO:$AO,TIMESHEETS!$F:$F,P$7,TIMESHEETS!$B:$B,$B21) -> 0 | Q21: =SUMIFS(TIMESHEETS!$AO:$AO,TIMESHEETS!$F:$F,Q$7,TIMESHEETS!$B:$B,$B21) -> 0 | ... AJ21: =SUMIFS(TIMESHEETS!$AO:$AO,TIMESHEETS!$F:$F,AJ$7,TIMESHEETS!$B:$B,$B21) -> 0 | AL21: =H21-SUM(J21:AJ21) -> 0
B23: 36416 | H23: 200 | J23: =SUMIFS(TIMESHEETS!$AQ:$AQ,TIMESHEETS!$F:$F,J$7,TIMESHEETS!$B:$B,$B24) -> 0 | K23: =SUMIFS(TIMESHEETS!$AQ:$AQ,TIMESHEETS!$F:$F,K$7,TIMESHEETS!$B:$B,$B24) -> 0 | L23: =SUMIFS(TIMESHEETS!$AQ:$AQ,TIMESHEETS!$F:$F,L$7,TIMESHEETS!$B:$B,$B24) -> 0 | M23: =SUMIFS(TIMESHEETS!$AQ:$AQ,TIMESHEETS!$F:$F,M$7,TIMESHEETS!$B:$B,$B24) -> 0 | N23: =SUMIFS(TIMESHEETS!$AQ:$AQ,TIMESHEETS!$F:$F,N$7,TIMESHEETS!$B:$B,$B24) -> 0 | O23: =SUMIFS(TIMESHEETS!$AQ:$AQ,TIMESHEETS!$F:$F,O$7,TIMESHEETS!$B:$B,$B24) -> 0 | P23: =SUMIFS(TIMESHEETS!$AQ:$AQ,TIMESHEETS!$F:$F,P$7,TIMESHEETS!$B:$B,$B24) -> 80 | Q23: =SUMIFS(TIMESHEETS!$AQ:$AQ,TIMESHEETS!$F:$F,Q$7,TIMESHEETS!$B:$B,$B24) -> 0 | ... AJ23: =SUMIFS(TIMESHEETS!$AQ:$AQ,TIMESHEETS!$F:$F,AJ$7,TIMESHEETS!$B:$B,$B24) -> 0 | AL23: =H23-SUM(J23:AJ23) -> 56 | AM23: =AL23/8 -> 7
B24: Descoteaux, Gerald | H24: 16 | J24: =SUMIFS(TIMESHEETS!$AO:$AO,TIMESHEETS!$F:$F,J$7,TIMESHEETS!$B:$B,$B24) -> 0 | K24: =SUMIFS(TIMESHEETS!$AO:$AO,TIMESHEETS!$F:$F,K$7,TIMESHEETS!$B:$B,$B24) -> 0 | L24: =SUMIFS(TIMESHEETS!$AO:$AO,TIMESHEETS!$F:$F,L$7,TIMESHEETS!$B:$B,$B24) -> 0 | M24: =SUMIFS(TIMESHEETS!$AO:$AO,TIMESHEETS!$F:$F,M$7,TIMESHEETS!$B:$B,$B24) -> 0 | N24: =SUMIFS(TIMESHEETS!$AO:$AO,TIMESHEETS!$F:$F,N$7,TIMESHEETS!$B:$B,$B24) -> 0 | O24: =SUMIFS(TIMESHEETS!$AO:$AO,TIMESHEETS!$F:$F,O$7,TIMESHEETS!$B:$B,$B24) -> 0 | P24: =SUMIFS(TIMESHEETS!$AO:$AO,TIMESHEETS!$F:$F,P$7,TIMESHEETS!$B:$B,$B24) -> 0 | Q24: =SUMIFS(TIMESHEETS!$AO:$AO,TIMESHEETS!$F:$F,Q$7,TIMESHEETS!$B:$B,$B24) -> 0 | ... AJ24: =SUMIFS(TIMESHEETS!$AO:$AO,TIMESHEETS!$F:$F,AJ$7,TIMESHEETS!$B:$B,$B24) -> 0 | AL24: =H24-SUM(J24:AJ24) -> 16
B26: 43318 | H26: 120 | J26: =SUMIFS(TIMESHEETS!$AQ:$AQ,TIMESHEETS!$F:$F,J$7,TIMESHEETS!$B:$B,$B27) -> 0 | K26: =SUMIFS(TIMESHEETS!$AQ:$AQ,TIMESHEETS!$F:$F,K$7,TIMESHEETS!$B:$B,$B27) -> 0 | L26: =SUMIFS(TIMESHEETS!$AQ:$AQ,TIMESHEETS!$F:$F,L$7,TIMESHEETS!$B:$B,$B27) -> 0 | M26: =SUMIFS(TIMESHEETS!$AQ:$AQ,TIMESHEETS!$F:$F,M$7,TIMESHEETS!$B:$B,$B27) -> 0 | N26: =SUMIFS(TIMESHEETS!$AQ:$AQ,TIMESHEETS!$F:$F,N$7,TIMESHEETS!$B:$B,$B27) -> 0 | O26: =SUMIFS(TIMESHEETS!$AQ:$AQ,TIMESHEETS!$F:$F,O$7,TIMESHEETS!$B:$B,$B27) -> 0 | P26: =SUMIFS(TIMESHEETS!$AQ:$AQ,TIMESHEETS!$F:$F,P$7,TIMESHEETS!$B:$B,$B27) -> 80 | Q26: =SUMIFS(TIMESHEETS!$AQ:$AQ,TIMESHEETS!$F:$F,Q$7,TIMESHEETS!$B:$B,$B27) -> 0 | ... AJ26: =SUMIFS(TIMESHEETS!$AQ:$AQ,TIMESHEETS!$F:$F,AJ$7,TIMESHEETS!$B:$B,$B27) -> 0 | AL26: =H26-SUM(J26:AJ26) -> 0 | AM26: =AL26/8 -> 0
B27: De Rose, Natale | H27: 16 | J27: =SUMIFS(TIMESHEETS!$AO:$AO,TIMESHEETS!$F:$F,J$7,TIMESHEETS!$B:$B,$B27) -> 0 | K27: =SUMIFS(TIMESHEETS!$AO:$AO,TIMESHEETS!$F:$F,K$7,TIMESHEETS!$B:$B,$B27) -> 0 | L27: =SUMIFS(TIMESHEETS!$AO:$AO,TIMESHEETS!$F:$F,L$7,TIMESHEETS!$B:$B,$B27) -> 0 | M27: =SUMIFS(TIMESHEETS!$AO:$AO,TIMESHEETS!$F:$F,M$7,TIMESHEETS!$B:$B,$B27) -> 0 | N27: =SUMIFS(TIMESHEETS!$AO:$AO,TIMESHEETS!$F:$F,N$7,TIMESHEETS!$B:$B,$B27) -> 0 | O27: =SUMIFS(TIMESHEETS!$AO:$AO,TIMESHEETS!$F:$F,O$7,TIMESHEETS!$B:$B,$B27) -> 0 | P27: =SUMIFS(TIMESHEETS!$AO:$AO,TIMESHEETS!$F:$F,P$7,TIMESHEETS!$B:$B,$B27) -> 0 | Q27: =SUMIFS(TIMESHEETS!$AO:$AO,TIMESHEETS!$F:$F,Q$7,TIMESHEETS!$B:$B,$B27) -> 0 | ... AJ27: =SUMIFS(TIMESHEETS!$AO:$AO,TIMESHEETS!$F:$F,AJ$7,TIMESHEETS!$B:$B,$B27) -> 0 | AL27: =H27-SUM(J27:AJ27) -> 16
B29: 39853 | H29: 160 | J29: =SUMIFS(TIMESHEETS!$AQ:$AQ,TIMESHEETS!$F:$F,J$7,TIMESHEETS!$B:$B,$B30) -> 0 | K29: =SUMIFS(TIMESHEETS!$AQ:$AQ,TIMESHEETS!$F:$F,K$7,TIMESHEETS!$B:$B,$B30) -> 0 | L29: =SUMIFS(TIMESHEETS!$AQ:$AQ,TIMESHEETS!$F:$F,L$7,TIMESHEETS!$B:$B,$B30) -> 0 | M29: =SUMIFS(TIMESHEETS!$AQ:$AQ,TIMESHEETS!$F:$F,M$7,TIMESHEETS!$B:$B,$B30) -> 0 | N29: =SUMIFS(TIMESHEETS!$AQ:$AQ,TIMESHEETS!$F:$F,N$7,TIMESHEETS!$B:$B,$B30) -> 0 | O29: =SUMIFS(TIMESHEETS!$AQ:$AQ,TIMESHEETS!$F:$F,O$7,TIMESHEETS!$B:$B,$B30) -> 0 | P29: =SUMIFS(TIMESHEETS!$AQ:$AQ,TIMESHEETS!$F:$F,P$7,TIMESHEETS!$B:$B,$B30) -> 80 | Q29: =SUMIFS(TIMESHEETS!$AQ:$AQ,TIMESHEETS!$F:$F,Q$7,TIMESHEETS!$B:$B,$B30) -> 0 | ... AJ29: =SUMIFS(TIMESHEETS!$AQ:$AQ,TIMESHEETS!$F:$F,AJ$7,TIMESHEETS!$B:$B,$B30) -> 0 | AL29: =H29-SUM(J29:AJ29) -> 0 | AM29: =AL29/8 -> 0
B30: Fortin, Veronique | H30: 16 | J30: =SUMIFS(TIMESHEETS!$AO:$AO,TIMESHEETS!$F:$F,J$7,TIMESHEETS!$B:$B,$B30) -> 0 | K30: =SUMIFS(TIMESHEETS!$AO:$AO,TIMESHEETS!$F:$F,K$7,TIMESHEETS!$B:$B,$B30) -> 8 | L30: =SUMIFS(TIMESHEETS!$AO:$AO,TIMESHEETS!$F:$F,L$7,TIMESHEETS!$B:$B,$B30) -> 0 | M30: =SUMIFS(TIMESHEETS!$AO:$AO,TIMESHEETS!$F:$F,M$7,TIMESHEETS!$B:$B,$B30) -> 0 | N30: =SUMIFS(TIMESHEETS!$AO:$AO,TIMESHEETS!$F:$F,N$7,TIMESHEETS!$B:$B,$B30) -> 0 | O30: =SUMIFS(TIMESHEETS!$AO:$AO,TIMESHEETS!$F:$F,O$7,TIMESHEETS!$B:$B,$B30) -> 0 | P30: =SUMIFS(TIMESHEETS!$AO:$AO,TIMESHEETS!$F:$F,P$7,TIMESHEETS!$B:$B,$B30) -> 0 | Q30: =SUMIFS(TIMESHEETS!$AO:$AO,TIMESHEETS!$F:$F,Q$7,TIMESHEETS!$B:$B,$B30) -> 0 | ... AJ30: =SUMIFS(TIMESHEETS!$AO:$AO,TIMESHEETS!$F:$F,AJ$7,TIMESHEETS!$B:$B,$B30) -> 0 | AL30: =H30-SUM(J30:AJ30) -> 0
B32: 42458 | H32: 120 | J32: =SUMIFS(TIMESHEETS!$AQ:$AQ,TIMESHEETS!$F:$F,J$7,TIMESHEETS!$B:$B,$B33) -> 0 | K32: =SUMIFS(TIMESHEETS!$AQ:$AQ,TIMESHEETS!$F:$F,K$7,TIMESHEETS!$B:$B,$B33) -> 0 | L32: =SUMIFS(TIMESHEETS!$AQ:$AQ,TIMESHEETS!$F:$F,L$7,TIMESHEETS!$B:$B,$B33) -> 0 | M32: =SUMIFS(TIMESHEETS!$AQ:$AQ,TIMESHEETS!$F:$F,M$7,TIMESHEETS!$B:$B,$B33) -> 0 | N32: =SUMIFS(TIMESHEETS!$AQ:$AQ,TIMESHEETS!$F:$F,N$7,TIMESHEETS!$B:$B,$B33) -> 0 | O32: =SUMIFS(TIMESHEETS!$AQ:$AQ,TIMESHEETS!$F:$F,O$7,TIMESHEETS!$B:$B,$B33) -> 0 | P32: =SUMIFS(TIMESHEETS!$AQ:$AQ,TIMESHEETS!$F:$F,P$7,TIMESHEETS!$B:$B,$B33) -> 80 | Q32: =SUMIFS(TIMESHEETS!$AQ:$AQ,TIMESHEETS!$F:$F,Q$7,TIMESHEETS!$B:$B,$B33) -> 0 | ... AJ32: =SUMIFS(TIMESHEETS!$AQ:$AQ,TIMESHEETS!$F:$F,AJ$7,TIMESHEETS!$B:$B,$B33) -> 0 | AL32: =H32-SUM(J32:AJ32) -> 0 | AM32: =AL32/8 -> 0
B33: Gadbois, Dominic | H33: 16 | J33: =SUMIFS(TIMESHEETS!$AO:$AO,TIMESHEETS!$F:$F,J$7,TIMESHEETS!$B:$B,$B33) -> 0 | K33: =SUMIFS(TIMESHEETS!$AO:$AO,TIMESHEETS!$F:$F,K$7,TIMESHEETS!$B:$B,$B33) -> 0 | L33: =SUMIFS(TIMESHEETS!$AO:$AO,TIMESHEETS!$F:$F,L$7,TIMESHEETS!$B:$B,$B33) -> 0 | M33: =SUMIFS(TIMESHEETS!$AO:$AO,TIMESHEETS!$F:$F,M$7,TIMESHEETS!$B:$B,$B33) -> 0 | N33: =SUMIFS(TIMESHEETS!$AO:$AO,TIMESHEETS!$F:$F,N$7,TIMESHEETS!$B:$B,$B33) -> 0 | O33: =SUMIFS(TIMESHEETS!$AO:$AO,TIMESHEETS!$F:$F,O$7,TIMESHEETS!$B:$B,$B33) -> 8 | P33: =SUMIFS(TIMESHEETS!$AO:$AO,TIMESHEETS!$F:$F,P$7,TIMESHEETS!$B:$B,$B33) -> 0 | Q33: =SUMIFS(TIMESHEETS!$AO:$AO,TIMESHEETS!$F:$F,Q$7,TIMESHEETS!$B:$B,$B33) -> 8 | ... AJ33: =SUMIFS(TIMESHEETS!$AO:$AO,TIMESHEETS!$F:$F,AJ$7,TIMESHEETS!$B:$B,$B33) -> 0 | AL33: =H33-SUM(J33:AJ33) -> -16
B35: 44165 | H35: 40 | J35: =SUMIFS(TIMESHEETS!$AQ:$AQ,TIMESHEETS!$F:$F,J$7,TIMESHEETS!$B:$B,$B36) -> 0 | K35: =SUMIFS(TIMESHEETS!$AQ:$AQ,TIMESHEETS!$F:$F,K$7,TIMESHEETS!$B:$B,$B36) -> 0 | L35: =SUMIFS(TIMESHEETS!$AQ:$AQ,TIMESHEETS!$F:$F,L$7,TIMESHEETS!$B:$B,$B36) -> 0 | M35: =SUMIFS(TIMESHEETS!$AQ:$AQ,TIMESHEETS!$F:$F,M$7,TIMESHEETS!$B:$B,$B36) -> 0 | N35: =SUMIFS(TIMESHEETS!$AQ:$AQ,TIMESHEETS!$F:$F,N$7,TIMESHEETS!$B:$B,$B36) -> 0 | O35: =SUMIFS(TIMESHEETS!$AQ:$AQ,TIMESHEETS!$F:$F,O$7,TIMESHEETS!$B:$B,$B36) -> 0 | P35: =SUMIFS(TIMESHEETS!$AQ:$AQ,TIMESHEETS!$F:$F,P$7,TIMESHEETS!$B:$B,$B36) -> 24 | Q35: =SUMIFS(TIMESHEETS!$AQ:$AQ,TIMESHEETS!$F:$F,Q$7,TIMESHEETS!$B:$B,$B36) -> 16 | ... AJ35: =SUMIFS(TIMESHEETS!$AQ:$AQ,TIMESHEETS!$F:$F,AJ$7,TIMESHEETS!$B:$B,$B36) -> 0 | AL35: =H35-SUM(J35:AJ35) -> 0 | AM35: =AL35/8 -> 0
B36: Knox Michaud, Jessy | H36: 16 | J36: =SUMIFS(TIMESHEETS!$AO:$AO,TIMESHEETS!$F:$F,J$7,TIMESHEETS!$B:$B,$B36) -> 0 | K36: =SUMIFS(TIMESHEETS!$AO:$AO,TIMESHEETS!$F:$F,K$7,TIMESHEETS!$B:$B,$B36) -> 0 | L36: =SUMIFS(TIMESHEETS!$AO:$AO,TIMESHEETS!$F:$F,L$7,TIMESHEETS!$B:$B,$B36) -> 0 | M36: =SUMIFS(TIMESHEETS!$AO:$AO,TIMESHEETS!$F:$F,M$7,TIMESHEETS!$B:$B,$B36) -> 0 | N36: =SUMIFS(TIMESHEETS!$AO:$AO,TIMESHEETS!$F:$F,N$7,TIMESHEETS!$B:$B,$B36) -> 0 | O36: =SUMIFS(TIMESHEETS!$AO:$AO,TIMESHEETS!$F:$F,O$7,TIMESHEETS!$B:$B,$B36) -> 0 | P36: =SUMIFS(TIMESHEETS!$AO:$AO,TIMESHEETS!$F:$F,P$7,TIMESHEETS!$B:$B,$B36) -> 0 | Q36: =SUMIFS(TIMESHEETS!$AO:$AO,TIMESHEETS!$F:$F,Q$7,TIMESHEETS!$B:$B,$B36) -> 0 | ... AJ36: =SUMIFS(TIMESHEETS!$AO:$AO,TIMESHEETS!$F:$F,AJ$7,TIMESHEETS!$B:$B,$B36) -> 0 | AL36: =H36-SUM(J36:AJ36) -> 0
B38: 40868 | H38: 200 | J38: =SUMIFS(TIMESHEETS!$AQ:$AQ,TIMESHEETS!$F:$F,J$7,TIMESHEETS!$B:$B,$B39) -> 8 | K38: =SUMIFS(TIMESHEETS!$AQ:$AQ,TIMESHEETS!$F:$F,K$7,TIMESHEETS!$B:$B,$B39) -> 32 | L38: =SUMIFS(TIMESHEETS!$AQ:$AQ,TIMESHEETS!$F:$F,L$7,TIMESHEETS!$B:$B,$B39) -> 0 | M38: =SUMIFS(TIMESHEETS!$AQ:$AQ,TIMESHEETS!$F:$F,M$7,TIMESHEETS!$B:$B,$B39) -> 0 | N38: =SUMIFS(TIMESHEETS!$AQ:$AQ,TIMESHEETS!$F:$F,N$7,TIMESHEETS!$B:$B,$B39) -> 0 | O38: =SUMIFS(TIMESHEETS!$AQ:$AQ,TIMESHEETS!$F:$F,O$7,TIMESHEETS!$B:$B,$B39) -> 0 | P38: =SUMIFS(TIMESHEETS!$AQ:$AQ,TIMESHEETS!$F:$F,P$7,TIMESHEETS!$B:$B,$B39) -> 80 | Q38: =SUMIFS(TIMESHEETS!$AQ:$AQ,TIMESHEETS!$F:$F,Q$7,TIMESHEETS!$B:$B,$B39) -> 0 | ... AJ38: =SUMIFS(TIMESHEETS!$AQ:$AQ,TIMESHEETS!$F:$F,AJ$7,TIMESHEETS!$B:$B,$B39) -> 0 | AL38: =H38-SUM(J38:AJ38) -> 0 | AM38: =AL38/8 -> 0
B39: Landry, Bernard | H39: 16 | J39: =SUMIFS(TIMESHEETS!$AO:$AO,TIMESHEETS!$F:$F,J$7,TIMESHEETS!$B:$B,$B39) -> 0 | K39: =SUMIFS(TIMESHEETS!$AO:$AO,TIMESHEETS!$F:$F,K$7,TIMESHEETS!$B:$B,$B39) -> 0 | L39: =SUMIFS(TIMESHEETS!$AO:$AO,TIMESHEETS!$F:$F,L$7,TIMESHEETS!$B:$B,$B39) -> 0 | M39: =SUMIFS(TIMESHEETS!$AO:$AO,TIMESHEETS!$F:$F,M$7,TIMESHEETS!$B:$B,$B39) -> 0 | N39: =SUMIFS(TIMESHEETS!$AO:$AO,TIMESHEETS!$F:$F,N$7,TIMESHEETS!$B:$B,$B39) -> 0 | O39: =SUMIFS(TIMESHEETS!$AO:$AO,TIMESHEETS!$F:$F,O$7,TIMESHEETS!$B:$B,$B39) -> 0 | P39: =SUMIFS(TIMESHEETS!$AO:$AO,TIMESHEETS!$F:$F,P$7,TIMESHEETS!$B:$B,$B39) -> 0 | Q39: =SUMIFS(TIMESHEETS!$AO:$AO,TIMESHEETS!$F:$F,Q$7,TIMESHEETS!$B:$B,$B39) -> 0 | ... AJ39: =SUMIFS(TIMESHEETS!$AO:$AO,TIMESHEETS!$F:$F,AJ$7,TIMESHEETS!$B:$B,$B39) -> 0 | AL39: =H39-SUM(J39:AJ39) -> 0
B41: 37093 | H41: 248 | J41: =SUMIFS(TIMESHEETS!$AQ:$AQ,TIMESHEETS!$F:$F,J$7,TIMESHEETS!$B:$B,$B42) -> 40 | K41: =SUMIFS(TIMESHEETS!$AQ:$AQ,TIMESHEETS!$F:$F,K$7,TIMESHEETS!$B:$B,$B42) -> 8 | L41: =SUMIFS(TIMESHEETS!$AQ:$AQ,TIMESHEETS!$F:$F,L$7,TIMESHEETS!$B:$B,$B42) -> 0 | M41: =SUMIFS(TIMESHEETS!$AQ:$AQ,TIMESHEETS!$F:$F,M$7,TIMESHEETS!$B:$B,$B42) -> 0 | N41: =SUMIFS(TIMESHEETS!$AQ:$AQ,TIMESHEETS!$F:$F,N$7,TIMESHEETS!$B:$B,$B42) -> 0 | O41: =SUMIFS(TIMESHEETS!$AQ:$AQ,TIMESHEETS!$F:$F,O$7,TIMESHEETS!$B:$B,$B42) -> 0 | P41: =SUMIFS(TIMESHEETS!$AQ:$AQ,TIMESHEETS!$F:$F,P$7,TIMESHEETS!$B:$B,$B42) -> 80 | Q41: =SUMIFS(TIMESHEETS!$AQ:$AQ,TIMESHEETS!$F:$F,Q$7,TIMESHEETS!$B:$B,$B42) -> 0 | ... AJ41: =SUMIFS(TIMESHEETS!$AQ:$AQ,TIMESHEETS!$F:$F,AJ$7,TIMESHEETS!$B:$B,$B42) -> 32 | AL41: =H41-SUM(J41:AJ41) -> 40 | AM41: =AL41/8 -> 5
B42: Lelievre, Anik | H42: 16 | J42: =SUMIFS(TIMESHEETS!$AO:$AO,TIMESHEETS!$F:$F,J$7,TIMESHEETS!$B:$B,$B42) -> 0 | K42: =SUMIFS(TIMESHEETS!$AO:$AO,TIMESHEETS!$F:$F,K$7,TIMESHEETS!$B:$B,$B42) -> 0 | L42: =SUMIFS(TIMESHEETS!$AO:$AO,TIMESHEETS!$F:$F,L$7,TIMESHEETS!$B:$B,$B42) -> 0 | M42: =SUMIFS(TIMESHEETS!$AO:$AO,TIMESHEETS!$F:$F,M$7,TIMESHEETS!$B:$B,$B42) -> 0 | N42: =SUMIFS(TIMESHEETS!$AO:$AO,TIMESHEETS!$F:$F,N$7,TIMESHEETS!$B:$B,$B42) -> 0 | O42: =SUMIFS(TIMESHEETS!$AO:$AO,TIMESHEETS!$F:$F,O$7,TIMESHEETS!$B:$B,$B42) -> 0 | P42: =SUMIFS(TIMESHEETS!$AO:$AO,TIMESHEETS!$F:$F,P$7,TIMESHEETS!$B:$B,$B42) -> 0 | Q42: =SUMIFS(TIMESHEETS!$AO:$AO,TIMESHEETS!$F:$F,Q$7,TIMESHEETS!$B:$B,$B42) -> 0 | ... AJ42: =SUMIFS(TIMESHEETS!$AO:$AO,TIMESHEETS!$F:$F,AJ$7,TIMESHEETS!$B:$B,$B42) -> 0 | AL42: =H42-SUM(J42:AJ42) -> 16
B44: 35884 | H44: 232 | J44: =SUMIFS(TIMESHEETS!$AQ:$AQ,TIMESHEETS!$F:$F,J$7,TIMESHEETS!$B:$B,$B45) -> 24 | K44: =SUMIFS(TIMESHEETS!$AQ:$AQ,TIMESHEETS!$F:$F,K$7,TIMESHEETS!$B:$B,$B45) -> 8 | L44: =SUMIFS(TIMESHEETS!$AQ:$AQ,TIMESHEETS!$F:$F,L$7,TIMESHEETS!$B:$B,$B45) -> 24 | M44: =SUMIFS(TIMESHEETS!$AQ:$AQ,TIMESHEETS!$F:$F,M$7,TIMESHEETS!$B:$B,$B45) -> 0 | N44: =SUMIFS(TIMESHEETS!$AQ:$AQ,TIMESHEETS!$F:$F,N$7,TIMESHEETS!$B:$B,$B45) -> 8 | O44: =SUMIFS(TIMESHEETS!$AQ:$AQ,TIMESHEETS!$F:$F,O$7,TIMESHEETS!$B:$B,$B45) -> 8 | P44: =SUMIFS(TIMESHEETS!$AQ:$AQ,TIMESHEETS!$F:$F,P$7,TIMESHEETS!$B:$B,$B45) -> 0 | Q44: =SUMIFS(TIMESHEETS!$AQ:$AQ,TIMESHEETS!$F:$F,Q$7,TIMESHEETS!$B:$B,$B45) -> 40 | ... AJ44: =SUMIFS(TIMESHEETS!$AQ:$AQ,TIMESHEETS!$F:$F,AJ$7,TIMESHEETS!$B:$B,$B45) -> 8 | AL44: =H44-SUM(J44:AJ44) -> 0 | AM44: =AL44/8 -> 0
B45: Letarte, Martin | H45: 16 | J45: =SUMIFS(TIMESHEETS!$AO:$AO,TIMESHEETS!$F:$F,J$7,TIMESHEETS!$B:$B,$B45) -> 0 | K45: =SUMIFS(TIMESHEETS!$AO:$AO,TIMESHEETS!$F:$F,K$7,TIMESHEETS!$B:$B,$B45) -> 0 | L45: =SUMIFS(TIMESHEETS!$AO:$AO,TIMESHEETS!$F:$F,L$7,TIMESHEETS!$B:$B,$B45) -> 0 | M45: =SUMIFS(TIMESHEETS!$AO:$AO,TIMESHEETS!$F:$F,M$7,TIMESHEETS!$B:$B,$B45) -> 16 | N45: =SUMIFS(TIMESHEETS!$AO:$AO,TIMESHEETS!$F:$F,N$7,TIMESHEETS!$B:$B,$B45) -> 0 | O45: =SUMIFS(TIMESHEETS!$AO:$AO,TIMESHEETS!$F:$F,O$7,TIMESHEETS!$B:$B,$B45) -> 0 | P45: =SUMIFS(TIMESHEETS!$AO:$AO,TIMESHEETS!$F:$F,P$7,TIMESHEETS!$B:$B,$B45) -> 0 | Q45: =SUMIFS(TIMESHEETS!$AO:$AO,TIMESHEETS!$F:$F,Q$7,TIMESHEETS!$B:$B,$B45) -> 0 | ... AJ45: =SUMIFS(TIMESHEETS!$AO:$AO,TIMESHEETS!$F:$F,AJ$7,TIMESHEETS!$B:$B,$B45) -> 0 | AL45: =H45-SUM(J45:AJ45) -> 0
H47: 0 | J47: =SUMIFS(TIMESHEETS!$AQ:$AQ,TIMESHEETS!$F:$F,J$7,TIMESHEETS!$B:$B,$B48) -> 0 | K47: =SUMIFS(TIMESHEETS!$AQ:$AQ,TIMESHEETS!$F:$F,K$7,TIMESHEETS!$B:$B,$B48) -> 0 | L47: =SUMIFS(TIMESHEETS!$AQ:$AQ,TIMESHEETS!$F:$F,L$7,TIMESHEETS!$B:$B,$B48) -> 0 | M47: =SUMIFS(TIMESHEETS!$AQ:$AQ,TIMESHEETS!$F:$F,M$7,TIMESHEETS!$B:$B,$B48) -> 0 | N47: =SUMIFS(TIMESHEETS!$AQ:$AQ,TIMESHEETS!$F:$F,N$7,TIMESHEETS!$B:$B,$B48) -> 0 | O47: =SUMIFS(TIMESHEETS!$AQ:$AQ,TIMESHEETS!$F:$F,O$7,TIMESHEETS!$B:$B,$B48) -> 0 | P47: =SUMIFS(TIMESHEETS!$AQ:$AQ,TIMESHEETS!$F:$F,P$7,TIMESHEETS!$B:$B,$B48) -> 0 | Q47: =SUMIFS(TIMESHEETS!$AQ:$AQ,TIMESHEETS!$F:$F,Q$7,TIMESHEETS!$B:$B,$B48) -> 0 | ... AJ47: =SUMIFS(TIMESHEETS!$AQ:$AQ,TIMESHEETS!$F:$F,AJ$7,TIMESHEETS!$B:$B,$B48) -> 0 | AL47: =H47-SUM(J47:AJ47) -> 0 | AM47: =AL47/8 -> 0
H48: 0 | J48: =SUMIFS(TIMESHEETS!$AO:$AO,TIMESHEETS!$F:$F,J$7,TIMESHEETS!$B:$B,$B48) -> 0 | K48: =SUMIFS(TIMESHEETS!$AO:$AO,TIMESHEETS!$F:$F,K$7,TIMESHEETS!$B:$B,$B48) -> 0 | L48: =SUMIFS(TIMESHEETS!$AO:$AO,TIMESHEETS!$F:$F,L$7,TIMESHEETS!$B:$B,$B48) -> 0 | M48: =SUMIFS(TIMESHEETS!$AO:$AO,TIMESHEETS!$F:$F,M$7,TIMESHEETS!$B:$B,$B48) -> 0 | N48: =SUMIFS(TIMESHEETS!$AO:$AO,TIMESHEETS!$F:$F,N$7,TIMESHEETS!$B:$B,$B48) -> 0 | O48: =SUMIFS(TIMESHEETS!$AO:$AO,TIMESHEETS!$F:$F,O$7,TIMESHEETS!$B:$B,$B48) -> 0 | P48: =SUMIFS(TIMESHEETS!$AO:$AO,TIMESHEETS!$F:$F,P$7,TIMESHEETS!$B:$B,$B48) -> 0 | Q48: =SUMIFS(TIMESHEETS!$AO:$AO,TIMESHEETS!$F:$F,Q$7,TIMESHEETS!$B:$B,$B48) -> 0 | ... AJ48: =SUMIFS(TIMESHEETS!$AO:$AO,TIMESHEETS!$F:$F,AJ$7,TIMESHEETS!$B:$B,$B48) -> 0 | AL48: =H48-SUM(J48:AJ48) -> 0
B50: 41204 | H50: 160 | J50: =SUMIFS(TIMESHEETS!$AQ:$AQ,TIMESHEETS!$F:$F,J$7,TIMESHEETS!$B:$B,$B51) -> 0 | K50: =SUMIFS(TIMESHEETS!$AQ:$AQ,TIMESHEETS!$F:$F,K$7,TIMESHEETS!$B:$B,$B51) -> 0 | L50: =SUMIFS(TIMESHEETS!$AQ:$AQ,TIMESHEETS!$F:$F,L$7,TIMESHEETS!$B:$B,$B51) -> 0 | M50: =SUMIFS(TIMESHEETS!$AQ:$AQ,TIMESHEETS!$F:$F,M$7,TIMESHEETS!$B:$B,$B51) -> 0 | N50: =SUMIFS(TIMESHEETS!$AQ:$AQ,TIMESHEETS!$F:$F,N$7,TIMESHEETS!$B:$B,$B51) -> 0 | O50: =SUMIFS(TIMESHEETS!$AQ:$AQ,TIMESHEETS!$F:$F,O$7,TIMESHEETS!$B:$B,$B51) -> 0 | P50: =SUMIFS(TIMESHEETS!$AQ:$AQ,TIMESHEETS!$F:$F,P$7,TIMESHEETS!$B:$B,$B51) -> 80 | Q50: =SUMIFS(TIMESHEETS!$AQ:$AQ,TIMESHEETS!$F:$F,Q$7,TIMESHEETS!$B:$B,$B51) -> 0 | ... AJ50: =SUMIFS(TIMESHEETS!$AQ:$AQ,TIMESHEETS!$F:$F,AJ$7,TIMESHEETS!$B:$B,$B51) -> 0 | AL50: =H50-SUM(J50:AJ50) -> 0 | AM50: =AL50/8 -> 0
B51: Pellerin, Pierre | H51: 16 | J51: =SUMIFS(TIMESHEETS!$AO:$AO,TIMESHEETS!$F:$F,J$7,TIMESHEETS!$B:$B,$B51) -> 0 | K51: =SUMIFS(TIMESHEETS!$AO:$AO,TIMESHEETS!$F:$F,K$7,TIMESHEETS!$B:$B,$B51) -> 0 | L51: =SUMIFS(TIMESHEETS!$AO:$AO,TIMESHEETS!$F:$F,L$7,TIMESHEETS!$B:$B,$B51) -> 0 | M51: =SUMIFS(TIMESHEETS!$AO:$AO,TIMESHEETS!$F:$F,M$7,TIMESHEETS!$B:$B,$B51) -> 0 | N51: =SUMIFS(TIMESHEETS!$AO:$AO,TIMESHEETS!$F:$F,N$7,TIMESHEETS!$B:$B,$B51) -> 0 | O51: =SUMIFS(TIMESHEETS!$AO:$AO,TIMESHEETS!$F:$F,O$7,TIMESHEETS!$B:$B,$B51) -> 0 | P51: =SUMIFS(TIMESHEETS!$AO:$AO,TIMESHEETS!$F:$F,P$7,TIMESHEETS!$B:$B,$B51) -> 0 | Q51: =SUMIFS(TIMESHEETS!$AO:$AO,TIMESHEETS!$F:$F,Q$7,TIMESHEETS!$B:$B,$B51) -> 0 | ... AJ51: =SUMIFS(TIMESHEETS!$AO:$AO,TIMESHEETS!$F:$F,AJ$7,TIMESHEETS!$B:$B,$B51) -> 0 | AL51: =H51-SUM(J51:AJ51) -> 16
B53: 34486 | H53: 200 | J53: =SUMIFS(TIMESHEETS!$AQ:$AQ,TIMESHEETS!$F:$F,J$7,TIMESHEETS!$B:$B,$B54) -> 0 | K53: =SUMIFS(TIMESHEETS!$AQ:$AQ,TIMESHEETS!$F:$F,K$7,TIMESHEETS!$B:$B,$B54) -> 8 | L53: =SUMIFS(TIMESHEETS!$AQ:$AQ,TIMESHEETS!$F:$F,L$7,TIMESHEETS!$B:$B,$B54) -> 16 | M53: =SUMIFS(TIMESHEETS!$AQ:$AQ,TIMESHEETS!$F:$F,M$7,TIMESHEETS!$B:$B,$B54) -> 16 | N53: =SUMIFS(TIMESHEETS!$AQ:$AQ,TIMESHEETS!$F:$F,N$7,TIMESHEETS!$B:$B,$B54) -> 8 | O53: =SUMIFS(TIMESHEETS!$AQ:$AQ,TIMESHEETS!$F:$F,O$7,TIMESHEETS!$B:$B,$B54) -> 16 | P53: =SUMIFS(TIMESHEETS!$AQ:$AQ,TIMESHEETS!$F:$F,P$7,TIMESHEETS!$B:$B,$B54) -> 80 | Q53: =SUMIFS(TIMESHEETS!$AQ:$AQ,TIMESHEETS!$F:$F,Q$7,TIMESHEETS!$B:$B,$B54) -> 8 | ... AJ53: =SUMIFS(TIMESHEETS!$AQ:$AQ,TIMESHEETS!$F:$F,AJ$7,TIMESHEETS!$B:$B,$B54) -> 0 | AL53: =H53-SUM(J53:AJ53) -> 0 | AM53: =AL53/8 -> 0
B54: Rodrigue, Frank | H54: 16 | J54: =SUMIFS(TIMESHEETS!$AO:$AO,TIMESHEETS!$F:$F,J$7,TIMESHEETS!$B:$B,$B54) -> 0 | K54: =SUMIFS(TIMESHEETS!$AO:$AO,TIMESHEETS!$F:$F,K$7,TIMESHEETS!$B:$B,$B54) -> 0 | L54: =SUMIFS(TIMESHEETS!$AO:$AO,TIMESHEETS!$F:$F,L$7,TIMESHEETS!$B:$B,$B54) -> 0 | M54: =SUMIFS(TIMESHEETS!$AO:$AO,TIMESHEETS!$F:$F,M$7,TIMESHEETS!$B:$B,$B54) -> 0 | N54: =SUMIFS(TIMESHEETS!$AO:$AO,TIMESHEETS!$F:$F,N$7,TIMESHEETS!$B:$B,$B54) -> 0 | O54: =SUMIFS(TIMESHEETS!$AO:$AO,TIMESHEETS!$F:$F,O$7,TIMESHEETS!$B:$B,$B54) -> 0 | P54: =SUMIFS(TIMESHEETS!$AO:$AO,TIMESHEETS!$F:$F,P$7,TIMESHEETS!$B:$B,$B54) -> 0 | Q54: =SUMIFS(TIMESHEETS!$AO:$AO,TIMESHEETS!$F:$F,Q$7,TIMESHEETS!$B:$B,$B54) -> 0 | ... AJ54: =SUMIFS(TIMESHEETS!$AO:$AO,TIMESHEETS!$F:$F,AJ$7,TIMESHEETS!$B:$B,$B54) -> 0 | AL54: =H54-SUM(J54:AJ54) -> 8
H56: 0 | J56: =SUMIFS(TIMESHEETS!$AQ:$AQ,TIMESHEETS!$F:$F,J$7,TIMESHEETS!$B:$B,$B57) -> 0 | K56: =SUMIFS(TIMESHEETS!$AQ:$AQ,TIMESHEETS!$F:$F,K$7,TIMESHEETS!$B:$B,$B57) -> 0 | L56: =SUMIFS(TIMESHEETS!$AQ:$AQ,TIMESHEETS!$F:$F,L$7,TIMESHEETS!$B:$B,$B57) -> 0 | M56: =SUMIFS(TIMESHEETS!$AQ:$AQ,TIMESHEETS!$F:$F,M$7,TIMESHEETS!$B:$B,$B57) -> 0 | N56: =SUMIFS(TIMESHEETS!$AQ:$AQ,TIMESHEETS!$F:$F,N$7,TIMESHEETS!$B:$B,$B57) -> 0 | O56: =SUMIFS(TIMESHEETS!$AQ:$AQ,TIMESHEETS!$F:$F,O$7,TIMESHEETS!$B:$B,$B57) -> 0 | P56: =SUMIFS(TIMESHEETS!$AQ:$AQ,TIMESHEETS!$F:$F,P$7,TIMESHEETS!$B:$B,$B57) -> 0 | Q56: =SUMIFS(TIMESHEETS!$AQ:$AQ,TIMESHEETS!$F:$F,Q$7,TIMESHEETS!$B:$B,$B57) -> 0 | ... AD56: =SUMIFS(TIMESHEETS!$AQ:$AQ,TIMESHEETS!$F:$F,AD$7,TIMESHEETS!$B:$B,$B57) -> 0 | AE56: 0 | AF56: =SUMIFS(TIMESHEETS!$AQ:$AQ,TIMESHEETS!$F:$F,AF$7,TIMESHEETS!$B:$B,$B57) -> 0 | AG56: =SUMIFS(TIMESHEETS!$AQ:$AQ,TIMESHEETS!$F:$F,AG$7,TIMESHEETS!$B:$B,$B57) -> 0 | AH56: =SUMIFS(TIMESHEETS!$AQ:$AQ,TIMESHEETS!$F:$F,AH$7,TIMESHEETS!$B:$B,$B57) -> 0 | AI56: =SUMIFS(TIMESHEETS!$AQ:$AQ,TIMESHEETS!$F:$F,AI$7,TIMESHEETS!$B:$B,$B57) -> 0 | AJ56: =SUMIFS(TIMESHEETS!$AQ:$AQ,TIMESHEETS!$F:$F,AJ$7,TIMESHEETS!$B:$B,$B57) -> 0 | AL56: 0 | AM56: =AL56/8 -> 0
H57: 0 | J57: =SUMIFS(TIMESHEETS!$AO:$AO,TIMESHEETS!$F:$F,J$7,TIMESHEETS!$B:$B,$B57) -> 0 | K57: =SUMIFS(TIMESHEETS!$AO:$AO,TIMESHEETS!$F:$F,K$7,TIMESHEETS!$B:$B,$B57) -> 0 | L57: =SUMIFS(TIMESHEETS!$AO:$AO,TIMESHEETS!$F:$F,L$7,TIMESHEETS!$B:$B,$B57) -> 0 | M57: =SUMIFS(TIMESHEETS!$AO:$AO,TIMESHEETS!$F:$F,M$7,TIMESHEETS!$B:$B,$B57) -> 0 | N57: =SUMIFS(TIMESHEETS!$AO:$AO,TIMESHEETS!$F:$F,N$7,TIMESHEETS!$B:$B,$B57) -> 0 | O57: =SUMIFS(TIMESHEETS!$AO:$AO,TIMESHEETS!$F:$F,O$7,TIMESHEETS!$B:$B,$B57) -> 0 | P57: =SUMIFS(TIMESHEETS!$AO:$AO,TIMESHEETS!$F:$F,P$7,TIMESHEETS!$B:$B,$B57) -> 0 | Q57: =SUMIFS(TIMESHEETS!$AO:$AO,TIMESHEETS!$F:$F,Q$7,TIMESHEETS!$B:$B,$B57) -> 0 | ... AJ57: =SUMIFS(TIMESHEETS!$AO:$AO,TIMESHEETS!$F:$F,AJ$7,TIMESHEETS!$B:$B,$B57) -> 0 | AL57: =H57-SUM(J57:AJ57) -> 0
B59: 42968 | H59: 120 | J59: =SUMIFS(TIMESHEETS!$AQ:$AQ,TIMESHEETS!$F:$F,J$7,TIMESHEETS!$B:$B,$B60) -> 0 | K59: =SUMIFS(TIMESHEETS!$AQ:$AQ,TIMESHEETS!$F:$F,K$7,TIMESHEETS!$B:$B,$B60) -> 0 | L59: =SUMIFS(TIMESHEETS!$AQ:$AQ,TIMESHEETS!$F:$F,L$7,TIMESHEETS!$B:$B,$B60) -> 0 | M59: =SUMIFS(TIMESHEETS!$AQ:$AQ,TIMESHEETS!$F:$F,M$7,TIMESHEETS!$B:$B,$B60) -> 0 | N59: =SUMIFS(TIMESHEETS!$AQ:$AQ,TIMESHEETS!$F:$F,N$7,TIMESHEETS!$B:$B,$B60) -> 0 | O59: =SUMIFS(TIMESHEETS!$AQ:$AQ,TIMESHEETS!$F:$F,O$7,TIMESHEETS!$B:$B,$B60) -> 0 | P59: =SUMIFS(TIMESHEETS!$AQ:$AQ,TIMESHEETS!$F:$F,P$7,TIMESHEETS!$B:$B,$B60) -> 0 | Q59: =SUMIFS(TIMESHEETS!$AQ:$AQ,TIMESHEETS!$F:$F,Q$7,TIMESHEETS!$B:$B,$B60) -> 8 | ... AJ59: =SUMIFS(TIMESHEETS!$AQ:$AQ,TIMESHEETS!$F:$F,AJ$7,TIMESHEETS!$B:$B,$B60) -> 0 | AL59: =H59-SUM(J59:AJ59) -> 0 | AM59: =AL59/8 -> 0
B60: Voster, Jean-Michel | H60: 16 | J60: =SUMIFS(TIMESHEETS!$AO:$AO,TIMESHEETS!$F:$F,J$7,TIMESHEETS!$B:$B,$B60) -> 0 | K60: =SUMIFS(TIMESHEETS!$AO:$AO,TIMESHEETS!$F:$F,K$7,TIMESHEETS!$B:$B,$B60) -> 0 | L60: =SUMIFS(TIMESHEETS!$AO:$AO,TIMESHEETS!$F:$F,L$7,TIMESHEETS!$B:$B,$B60) -> 8 | M60: =SUMIFS(TIMESHEETS!$AO:$AO,TIMESHEETS!$F:$F,M$7,TIMESHEETS!$B:$B,$B60) -> 0 | N60: =SUMIFS(TIMESHEETS!$AO:$AO,TIMESHEETS!$F:$F,N$7,TIMESHEETS!$B:$B,$B60) -> 0 | O60: =SUMIFS(TIMESHEETS!$AO:$AO,TIMESHEETS!$F:$F,O$7,TIMESHEETS!$B:$B,$B60) -> 0 | P60: =SUMIFS(TIMESHEETS!$AO:$AO,TIMESHEETS!$F:$F,P$7,TIMESHEETS!$B:$B,$B60) -> 0 | Q60: =SUMIFS(TIMESHEETS!$AO:$AO,TIMESHEETS!$F:$F,Q$7,TIMESHEETS!$B:$B,$B60) -> 16 | ... AJ60: =SUMIFS(TIMESHEETS!$AO:$AO,TIMESHEETS!$F:$F,AJ$7,TIMESHEETS!$B:$B,$B60) -> 0 | AL60: =H60-SUM(J60:AJ60) -> -24
J62: =SUMIFS(TIMESHEETS!$AQ:$AQ,TIMESHEETS!$F:$F,J$7,TIMESHEETS!$B:$B,$B63) -> 0 | K62: =SUMIFS(TIMESHEETS!$AQ:$AQ,TIMESHEETS!$F:$F,K$7,TIMESHEETS!$B:$B,$B63) -> 0 | L62: =SUMIFS(TIMESHEETS!$AQ:$AQ,TIMESHEETS!$F:$F,L$7,TIMESHEETS!$B:$B,$B63) -> 0 | M62: =SUMIFS(TIMESHEETS!$AQ:$AQ,TIMESHEETS!$F:$F,M$7,TIMESHEETS!$B:$B,$B63) -> 0 | N62: =SUMIFS(TIMESHEETS!$AQ:$AQ,TIMESHEETS!$F:$F,N$7,TIMESHEETS!$B:$B,$B63) -> 0 | O62: =SUMIFS(TIMESHEETS!$AQ:$AQ,TIMESHEETS!$F:$F,O$7,TIMESHEETS!$B:$B,$B63) -> 0 | P62: =SUMIFS(TIMESHEETS!$AQ:$AQ,TIMESHEETS!$F:$F,P$7,TIMESHEETS!$B:$B,$B63) -> 0 | Q62: =SUMIFS(TIMESHEETS!$AQ:$AQ,TIMESHEETS!$F:$F,Q$7,TIMESHEETS!$B:$B,$B63) -> 0 | ... AJ62: =SUMIFS(TIMESHEETS!$AQ:$AQ,TIMESHEETS!$F:$F,AJ$7,TIMESHEETS!$B:$B,$B63) -> 0 | AL62: =H62-SUM(J62:AJ62) -> 0
...
